Workbook
Name _Regression_Int: 1
Name Area_stampa_MI: #REF!
Name solver_lin: 0
Name solver_num: 0
Name solver_opt: #REF!
Name solver_typ: 1
Name solver_val: 0

Sheet DASHBOARD
A1: APRI 2026 — DASHBOARD ECONOMICO-FINANZIARIA
A2: Modello aggiornato • Revisione finanziaria • Input → Elaborazione → Risultati
A4: INPUT UTENTE | C4: PARAMETRI AGGIORNATI | E4: RISULTATI
A5: Celle gialle | C5: Celle rosse | E5: Celle verdi
A7: SEZIONE | B7: FUNZIONE | C7: COSA DEVI FARE | D7: DOVE LEGGI IL RISULTATO | E7: STATO | F7: NOTE
A8: APRI | B8: Dati e modello principale | C8: Compila solo le celle gialle | D8: Celle verdi / risultati del modello | E8: OPERATIVO | F8: Foglio principale
A9: AGGIORNAMENTO 2026 | B9: Parametri e revisione | C9: Controlla i parametri evidenziati | D9: Confronto originale / aggiornato | E9: VERIFICATO | F9: Fonte e ratio nei commenti
A12: PARAMETRI FINANZIARI 2026
A13: Costo finanziamento benchmark | B13: 0.0434 | C13: Banca d’Italia — nuovi prestiti imprese
A14: Remunerazione liquidità benchmark | B14: 0.0065 | C14: Banca d’Italia — depositi
A15: Inflazione NIC | B15: 0.029 | C15: ISTAT — luglio 2026, dato definitivo
A16: IRES | B16: 0.24 | C16: Aliquota ordinaria di riferimento
A17: IRAP | B17: 0.039 | C17: Aliquota ordinaria di riferimento
A18: IVA ordinaria | B18: 0.22 | C18: Da verificare per categoria merceologica

Sheet AGGIORNAMENTO 2026
A1: AGGIORNAMENTO MODELLO APRI
A2: Data aggiornamento | B2: 13/08/2026
A3: Versione | B3: 2026
A4: Criterio | B4: Sono stati aggiornati i parametri obsoleti; le formule mantengono la logica originaria.
A5: Colore rosso | B5: Valore/formula modificato rispetto all'originale
A7: PARAMETRO | B7: CELLA | C7: ORIGINALE | D7: AGGIORNATO | E7: FONTE/CRITERIO | F7: NOTE
A8: Data elaborazione | B8: APRI!E1 | C8: 14/06/2007 | D8: 13/08/2026 | E8: Data corrente | F8: Aggiornata
A9: Inflazione beni largo consumo (proxy) | B9: APRI!C13 | C9: 2,50% | D9: 2,80% | E9: ISTAT, luglio 2026 | F9: Usata come proxy dell'inflazione corrente; il dato NIC annuo di luglio 2026 è +2,8%.
A10: Incremento costi | B10: APRI!C43 | C10: 2,50% | D10: 2,80% | E10: ISTAT, luglio 2026 | F10: Allineato al dato inflattivo generale; modificabile per scenario.
A11: Tasso passivo c/c | B11: APRI!C49 | C11: 5,00% | D11: 4,34% | E11: Banca d'Italia, maggio 2026 | F11: Proxy prudenziale: tasso nuovi prestiti alle società non finanziarie fino a 1 mln.
A12: Tasso attivo c/c | B12: APRI!C50 | C12: 1,50% | D12: 0,65% | E12: Banca d'Italia, maggio 2026 | F12: Tasso medio passivo sui depositi in essere; usato come proxy del rendimento della liquidità.
A13: IRAP | B13: APRI!C51 | C13: 4,25% | D13: 3,90% | E13: MEF | F13: Aliquota ordinaria nazionale; eventuali maggiorazioni regionali non incluse.
A14: IRES | B14: APRI!C52 | C14: 33,00% | D14: 24,00% | E14: Agenzia Entrate | F14: Aliquota ordinaria IRES vigente.
A15: IVA ordinaria cespiti | B15: APRI!B83 | C15: 20,00% | D15: 22,00% | E15: Normativa IVA italiana | F15: Aliquota ordinaria.
A16: Leasing immobiliare | B16: APRI!D93 | C16: 5,00% | D16: 4,34% | E16: Banca d'Italia, maggio 2026 | F16: Proxy per costo del finanziamento corporate fino a 1 mln.
A17: Leasing mobiliare | B17: APRI!D94 | C17: 5,00% | D17: 4,34% | E17: Banca d'Italia, maggio 2026 | F17: Proxy per costo del finanziamento corporate fino a 1 mln.
A18: Leasing d'azienda | B18: APRI!D95 | C18: 5,00% | D18: 4,34% | E18: Banca d'Italia, maggio 2026 | F18: Proxy per costo del finanziamento corporate fino a 1 mln.
... A20: Mutuo 2 | B20: APRI!D98 | C20: 5,00% | D20: 4,34% | E20: Banca d'Italia, maggio 2026 | F20: Proxy per costo del finanziamento corporate fino a 1 mln.
A23: REVISIONE FINANZIARIA DEL MODELLO
A24: Controllo #VALUE! | B24: Corretto | C24: Le formule dei piani di ammortamento restituivano "" (testo) come saldo residuo; il valore veniva poi moltiplicato per il tasso, generando #VALUE!. I saldi inattivi ora restituiscono 0.
A25: C49 / tasso passivo c/c | B25: 4,34% | C25: Aggiornato al dato maggio 2026 Banca d’Italia per nuovi prestiti alle imprese fino a 1 milione di euro. È un benchmark, non una quotazione bancaria specifica.
A26: C50 / tasso attivo c/c | B26: 0,65% | C26: Aggiornato al dato maggio 2026 Banca d’Italia sui depositi in essere.
A27: C13 / inflazione beni largo consumo | B27: 2,90% | C27: Parametro ricondotto all’inflazione NIC di luglio 2026; il carrello della spesa è però +1,3%, quindi il valore va inteso come ipotesi generale e non come indice specifico retail.
A28: C43 / incremento costi | B28: 2,90% | C28: Allineato al parametro inflattivo generale luglio 2026.
A29: C51 / IRAP | B29: 3,90% | C29: Aliquota ordinaria di riferimento; eventuale maggiorazione/differenziazione regionale non modellata.
A30: C52 / IRES | B30: 24,00% | C30: Aliquota ordinaria IRES aggiornata.
A31: B83 / IVA ordinaria | B31: 22,00% | C31: Aliquota ordinaria IVA vigente; le aliquote specifiche per categorie merceologiche restano da verificare separatamente.
A32: D93:D98 / finanziamenti | B32: 4,34% | C32: Benchmark unico per finanziamenti/leasing nel modello, coerente con il dato Banca d’Italia maggio 2026 per prestiti alle imprese fino a 1 milione. Per un preventivo reale il tasso va sostituito con il TAN/TAEG effettivo.
A33: Formula finanziaria | B33: PMT mantenuta | C33: Le rate restano calcolate con PMT su periodicità trimestrale. È stata corretta la propagazione dei saldi vuoti nei piani di ammortamento senza alterare la logica economica quando il debito è attivo.
A35: Formula audit
A36: Sono state sostituite le restituzioni "" dei saldi residui nei piani di rimborso con 0, evitando errori di tipo e mantenendo invariati i calcoli quando il finanziamento è inattivo.

Sheet APRI
A1: ZONA INPUT DATI: | D1: data elab.: | E1: 2026-08-13 | F1: note: | L1: LEGENDA | M1: ROSSO = parametro aggiornato 2026 | AP1: INPUT UTENTE
A2: INCASSI: | C2: 5800 | D2: incidenza | E2: m.l. | F2: iva | G2: DESCRIZIONE AGGIUNTIVA: | AP2: Celle gialle: inserisci / aggiorna i dati
A3: SALA | C3: =($C$2*D3)*(1-F3) -> 2839.1 | D3: 0.55 | E3: 0.225 | F3: 0.11
A4: S.& L. | C4: =($C$2*D4)*(1-F4) -> 1173.92 | D4: 0.22 | E4: 0.225 | F4: 0.08 | AP4: PARAMETRI 2026
A5: PESCE | C5: =($C$2*D5)*(1-F5) -> 165.3 | D5: 0.03 | E5: 0.225 | F5: 0.05 | AP5: Celle rosse: valori aggiornati
A6: CARNI | C6: =($C$2*D6)*(1-F6) -> 584.64 | D6: 0.12 | E6: 0.225 | F6: 0.16
A7: ORTO | C7: =($C$2*D7)*(1-F7) -> 445.44 | D7: 0.08 | E7: 0.225 | F7: 0.04 | AP7: RISULTATI
A8: TOTALE - vendite: | C8: =SUM(C3:C7) -> 5208.4 | D8: =SUM(D3:D7) -> 1 | E8: =(+C3*E3+C4*E4+C5*E5+C6*E6+C7*E7)/C8 -> 0.225 | F8: =D3*F3+D4*F4+D5*F5+D6*F6+D7*F7 -> 0.102 | AP8: Celle verdi: risultati da leggere
A9: ANNO 1: mesi di vendita | C9: 12 | D9: minor ML nel primo anno
A10: Mesi di preapertura (costi a c\economico) | C10: 0 | E10: 0.03 | F10: =IF(CALCOLI!K48=0,"ERR","") | G10: =IF(F10="ERR","mesi preaperura eccessivi","")
C11: anno 1 | E11: anno 2 | G11: anno 3 | I11: anno 4
A12: ANNI SUCCESSIVI: | C12: input man. | E12: =+C12 -> input man. | G12: =+E12 -> input man. | H12: automatico | I12: =+G12 -> input man. | J12: automatico
A13: INFLAZ BENI LARGO CONSUMO | C13: 0.029 | D13: =IF(C13>0,"","ERR") | E13: =+C13 -> 0.029 | F13: =+C13 -> 0.029 | H13: =$C$13 -> 0.029 | J13: =$C$13 -> 0.029
A14: INCASSI | C14: 4800 | D14: =IF(C14>0,"","ERR") | E14: 5300 | F14: =IF(E14>0,"","ERR") | H14: =+C2 -> 5800 | J14: =IF(I13>0.001,H14*(1+I13),H14*(1+J13)) -> 5968.2
A15: MARGINE LORDO | C15: 0.19 | D15: =IF(C15>0,"","ERR") | E15: 0.205 | F15: =IF(E15>0,"","ERR") | H15: =+E8 -> 0.225 | J15: =$E$8 -> 0.225
A16: =IF(D16="ERR","manca dato inflazione","") | B16: =IF(OR(E16="ERR",G16="ERR",I16="ERR"),"sia % che mln","") | D16: =IF(C13=0,"ERR","") | G16: =IF(AND(G13<>0,G14>0),"ERR","") | I16: =IF(AND(I13<>0,I14>0),"ERR","")
A17: COSTO DEL LAVORO: | C17: obiettivo | D17: calcolato | E17: obiettivo | F17: calcolato | G17: obiettivo | H17: calcolato | I17: obiettivo | J17: calcolato
A18: OBIETT.PRODUTTIVITA' | C18: 238 | D18: =(C124/C9*12)/C25 -> 228.57143 | E18: =C18*(1+E13) -> 244.902 | F18: =E124/E25 -> 244.902 | G18: =E18*(1+H13) -> 252.00416 | H18: =G124/G25 -> 252.00416 | I18: =G18*(1+J13) -> 259.31228 | J18: =I124/I25 -> 259.31228
A19: NR. DIPEND.NECESSARI | C19: =IF(C124>0,C124/C18,"") -> 20.168067 | D19: =(D18-C18)/C18 -> -0.039615846 | E19: =IF(E124>0,E124/E18,"") -> 21.64131 | F19: =(F18-E18)/E18 -> 0 | G19: =IF(G124>0,G124/G18,"") -> 23.015493 | H19: =(H18-G18)/G18 -> 0 | I19: =IF(I124>0,I124/I18,"") -> 23.015493 | J19: =(J18-I18)/I18 -> 0
A20: di cui: | C20: NR.dipendenti | D20: Costo x Unità | E20: NR.dipendenti | F20: Costo x Unità | G20: NR.dipendenti | H20: Costo x Unità | I20: NR.dipendenti | J20: Costo x Unità
A21: CAPO NEGOZIO | C21: 1 | D21: 41.5 | E21: =C21 -> 1 | F21: =D21*(1+$D$43) -> 42.7035 | G21: =+E21 -> 1 | H21: =F21*(1+$E$43) -> 43.941901 | I21: =G21 -> 1 | J21: =H21*(1+$F$43) -> 45.216217
A22: CAPI REPARTO + SOCI | C22: 4 | D22: 31.8 | E22: =C22 -> 4 | F22: =D22*(1+$D$43) -> 32.7222 | G22: =+E22 -> 4 | H22: =F22*(1+$E$43) -> 33.671144 | I22: =G22 -> 4 | J22: =H22*(1+$F$43) -> 34.647607
A23: ADDETTI S/ SGRAVIO | C23: 7 | D23: 25 | E23: =+C23 -> 7 | F23: =D23*(1+$D$43) -> 25.725 | G23: =+E23 -> 7 | H23: =F23*(1+$E$43) -> 26.471025 | I23: =+I124/I18-I21-I22-I24 -> 13.015493 | J23: =H23*(1+$F$43) -> 27.238685
A24: ADDETTI C/ SGRAVIO | C24: 9 | D24: 18.5 | E24: =+E124/E18-E21-E22-E23 -> 9.6413096 | F24: =D24*(1+$D$43) -> 19.0365 | G24: =+G124/G18-G21-G22-G23 -> 11.015493 | H24: =F24*(1+$E$43) -> 19.588558 | I24: 5 | J24: =H24*(1+$F$43) -> 20.156627
A25: TOTALE DIPENDENTI (costo annuo) | C25: =SUM(C21:C24) -> 21 | D25: =C21*D21+C22*D22+C23*D23+C24*D24 -> 510.2 | E25: =SUM(E21:E24) -> 21.64131 | F25: =E21*F21+E22*F22+E23*F23+E24*F24 -> 537.20409 | G25: =SUM(G21:G24) -> 23.015493 | H25: =G21*H21+G22*H22+G23*H23+G24*H24 -> 579.70129 | I25: =SUM(I21:I24) -> 23.015493 | J25: =I21*J21+I22*J22+I23*J23+I24*J24 -> 639.1147
A27: IMMOBILE: | C27: di proprietà | D27: in affitto | E27: riaffittati | F27: Tot.disponib. | G27: anno | H27: affitto | I27: ricavo | J27: totale
A28: MQ. | D28: 1500 | F28: =+C28+D28-E28 -> 1500
A29: di cui: AREA VENDITA | F29: 1000 | G29: 1 | H29: =+D31 -> 92.34 | I29: =+E32 -> 0 | J29: =+H29-I29 -> 92.34
A30: COSTO IMMOBILIARE €/mq | C30: =+C28*B30/1000 -> 0 | G30: 2 | H30: =D31*(1+$D$43) -> 95.01786 | I30: =E32*(1+$D$43) -> 0 | J30: =+H30-I30 -> 95.01786
A31: COSTO DI AFFITTO €/mq mese | B31: 5.13 | D31: =(+D28*B31*12)/1000 -> 92.34 | G31: 3 | H31: =H30*(1+$D$43) -> 97.773378 | I31: =I30*(1+$D$43) -> 0 | J31: =+H31-I31 -> 97.773378
A32: RICAVO RIAFFITTO €/mq mese | E32: =+B32*12*E28/1000 -> 0 | G32: 4 | H32: =H31*(1+$D$43) -> 100.60881 | I32: =I31*(1+$D$43) -> 0 | J32: =+H32-I32 -> 100.60881
A34: AFFITTO AZIENDA | C34: INCASSI | D34: VENDITE | E34: ANNO | F34: TOT.AFFITTO
E35: 1 | F35: =+CALCOLI!K21 -> 0
A36: 1° scaglione | B36: 0 | C36: 0 | D36: 0 | E36: 2 | F36: =+CALCOLI!L21 -> 0 | O36: 0.10786696 | P36: 816553.81
A37: 2° scaglione | B37: su eccedenza 1° scagl. | C37: 0 | D37: 0 | E37: 3 | F37: =+CALCOLI!M21 -> 0
A38: MINIMO GARANTITO (Mln) | B38: 0 | E38: 4 | F38: =+CALCOLI!N21 -> 0
A39: =IF(D39="ERR","controllo % sia su incassi che vendite","") | D39: =IF(AND(C36>0,D36>0),"ERR",IF(AND(C37>0,D37>0),"ERR",IF(AND(C36>0,D37>0),"ERR",IF(AND(D36>0,C37>0),"ERR",""))))
A40: =IF(D40="ERR","controllo % su 2° scaglione e importo 1° scaglione","") | D40: =IF(AND(C37>0,B36=0),"ERR",IF(AND(D37>0,B36=0),"ERR",IF(AND(B36>0,C36>0,C37=0),"ERR",IF(AND(B36>0,D36>0,D37=0),"ERR",""))))
A41: INPUT PARAMETRI VARI | D41: ANNO SUCCESS. SU PRECED. - INC. ANNO
A42: VOCI: | B42: CONTROLLO | C42: ANNO 1 | D42: ANNO 2 | E42: ANNO 3 | F42: 4 ANNO
...

Sheet CALCOLI
B2: CALCOLO IVA | D2: ANNO 1 | E2: ANNO 2 | F2: ANNO 3 | G2: ANNO 4 | J2: CALCOLO AFFITTO DI AZIENDA
B3: RIPORTO CREDITO | D3: 0 | E3: =IF(D16>0,+D16,0) -> 36.565858 | F3: =IF(E16>0,+E16,0) -> 22.122479 | G3: =IF(F16>0,+F16,0) -> 5.8211748 | K3: 1 | L3: 2 | M3: 3 | N3: 4
B4: CESPITI | D4: =IF(APRI!C119>0,(APRI!C112*APRI!$B$84+APRI!C113*APRI!$B$85+APRI!C114*APRI!$B$86+APRI!C115*APRI!$B$87+APRI!C118*APRI!$B$83),0) -> 64.24 | E4: =IF(APRI!E119>0,(APRI!E112*APRI!$B$84+APRI!E113*APRI!$B$85+APRI!E114*APRI!$B$86+APRI!E115*APRI!$B$87+APRI!E118*APRI!$B$83),0) -> 0 | F4: =IF(APRI!G119>0,(APRI!G112*APRI!$B$84+APRI!G113*APRI!$B$85+APRI!G114*APRI!$B$86+APRI!G115*APRI!$B$87+APRI!G118*APRI!$B$83),0) -> 0 | G4: =IF(APRI!I119>0,(APRI!I112*APRI!$B$84+APRI!I113*APRI!$B$85+APRI!I114*APRI!$B$86+APRI!I115*APRI!$B$87+APRI!I118*APRI!$B$83),0) -> 0 | J4: min.gar. | K4: =+APRI!B38/12*APRI!C9 -> 0 | L4: =+APRI!B38*(1+APRI!F13) -> 0 | M4: =+L4*(1+APRI!H13) -> 0 | N4: =+M4*(1+APRI!J13) -> 0
B5: SU 1^ FORNITURA | D5: =IF(APRI!C59*APRI!D59>1,APRI!C59*APRI!D59,0) -> 25.5 | J5: INCASSI | K5: =IF(APRI!$C$36>APRI!$D$36,APRI!C124,0) -> 0 | L5: =IF(APRI!$C$36>APRI!$D$36,APRI!E124,0) -> 0 | M5: =IF(APRI!$C$36>APRI!$D$36,APRI!G124,0) -> 0 | N5: =IF(APRI!$C$36>APRI!$D$36,APRI!I124,0) -> 0
B6: sdo iniziale | D6: =SUM(D3:D5) -> 89.74 | E6: =SUM(E3:E5) -> 36.565858 | F6: =SUM(F3:F5) -> 22.122479 | G6: =SUM(G3:G5) -> 5.8211748 | J6: 1° SCAGLIONE | K6: =IF(AND(K5>0,APRI!$B$36>0),+APRI!$B$36/12*APRI!C9,IF(AND(K5>0,APRI!$B$36=0),K5,0)) -> 0 | L6: =IF(AND(L5>0,APRI!$B$36>0),+APRI!$B$36*(1+APRI!F13),IF(AND(L5>0,APRI!$B$36=0),L5,0)) -> 0 | M6: =IF(AND(M5>0,APRI!$B$36>0),+L6*(1+APRI!H13),IF(AND(M5>0,APRI!$B$36=0),M5,0)) -> 0 | N6: =IF(AND(N5>0,APRI!$B$36>0),+M6*(1+APRI!J13),IF(AND(N5>0,APRI!$B$36=0),N5,0)) -> 0
B7: SPESE GENERALI | D7: =APRI!C78*APRI!$B$83 -> 33 | E7: =APRI!D78*APRI!$B$83 -> 33.8734 | F7: =APRI!E78*APRI!$B$83 -> 35.171253 | G7: =APRI!F78*APRI!$B$83 -> 36.782715 | J7: % 1° SCAGLIONE | K7: =IF(APRI!C36>APRI!D36,APRI!C36,0) -> 0 | L7: =+K7 -> 0 | M7: =+L7 -> 0 | N7: =+M7 -> 0
B8: TRASPORTI | D8: =-APRI!C127*CALCOLI!$D$48 -> 5.49576 | E8: =-APRI!E127*CALCOLI!$D$48 -> 6.068235 | F8: =-APRI!G127*CALCOLI!$D$48 -> 6.64071 | G8: =-APRI!I127*CALCOLI!$D$48 -> 6.8332906 | J8: tot 1° | K8: =+K6*K7 -> 0 | L8: =+L6*L7 -> 0 | M8: =+M6*M7 -> 0 | N8: =+N6*N7 -> 0
B9: MATERIALE CONSUMO | D9: =-APRI!C128*APRI!$B$83 -> 6.638016 | E9: =-APRI!E128*APRI!$B$83 -> 7.329476 | F9: =-APRI!G128*APRI!$B$83 -> 8.020936 | G9: =-APRI!I128*APRI!$B$83 -> 8.2535431 | J9: 2° SCAGLIONE | K9: =IF(K5>K6,+K5-K6,0) -> 0 | L9: =IF(L5>L6,+L5-L6,0) -> 0 | M9: =IF(M5>M6,+M5-M6,0) -> 0 | N9: =IF(N5>N6,+N5-N6,0) -> 0
B10: LEASING\AFFITTI | D10: =(APRI!C135+APRI!C134)*APRI!$B$83 -> 40.744754 | E10: =(APRI!E135+APRI!E134)*APRI!$B$83 -> 41.333883 | F10: =(+APRI!G134+APRI!G135)*APRI!$B$83 -> 41.940097 | G10: =(APRI!I135+APRI!I134)*APRI!$B$83 -> 42.563892 | J10: %2° SCAGLIONE | K10: =IF(APRI!C37>APRI!D37,APRI!C37,0) -> 0 | L10: =+K10 -> 0 | M10: =+L10 -> 0 | N10: =+M10 -> 0
B11: PUBBLICITA' | D11: =APRI!C136*APRI!$B$83 -> 9.48288 | E11: =APRI!E136*APRI!$B$83 -> 10.47068 | F11: =APRI!G136*APRI!$B$83 -> 11.45848 | G11: =APRI!I136*APRI!$B$83 -> 11.790776 | J11: tot2° | K11: =+K9*K10 -> 0 | L11: =+L9*L10 -> 0 | M11: =+M9*M10 -> 0 | N11: =+N9*N10 -> 0
B12: TOTALE IVA A CREDITO | D12: =SUM(D6:D11) -> 185.10141 | E12: =SUM(E6:E11) -> 135.64153 | F12: =SUM(F6:F11) -> 125.35395 | G12: =SUM(G6:G11) -> 112.04539 | J12: TOTALE | K12: =+K8+K11 -> 0 | L12: =+L8+L11 -> 0 | M12: =+M8+M11 -> 0 | N12: =+N8+N11 -> 0
B13: IVA SU RICAVI | D13: =-APRI!C126*CALCOLI!$D$48 -> -83.535552 | E13: =-APRI!E126*CALCOLI!$D$48 -> -99.519054 | F13: =-APRI!G126*CALCOLI!$D$48 -> -119.53278 | G13: =-APRI!I126*CALCOLI!$D$48 -> -122.99923 | J13: VENDITE | K13: =IF(APRI!$D$36>APRI!$C$36,APRI!C125,0) -> 0 | L13: =IF(APRI!$D$36>APRI!$C$36,APRI!E125,0) -> 0 | M13: =IF(APRI!$D$36>APRI!$C$36,APRI!G125,0) -> 0 | N13: =IF(APRI!$D$36>APRI!$C$36,APRI!I125,0) -> 0
B14: SALDO (+credito \ - debito) | D14: =+D13+D12 -> 101.56586 | E14: =+E13+E12 -> 36.122479 | F14: =+F13+F12 -> 5.8211748 | G14: =+G13+G12 -> -10.953839 | J14: 1° SCAGLIONE | K14: =IF(APRI!$B$36>0,+APRI!$B$36/12*APRI!C9,K13) -> 0 | L14: =IF(APRI!B36>0,+APRI!B36*(1+APRI!F13),L13) -> 0 | M14: =IF(APRI!$B$36>0,+L14*(1+APRI!H13),M13) -> 0 | N14: =IF(APRI!$B$36>0,+M14*(1+APRI!J13),N13) -> 0
B15: IVA A RIMBORSO | D15: =-APRI!C106 -> -65 | E15: =-APRI!D106 -> -14 | F15: =-APRI!E106 -> 0 | G15: =-APRI!F106 -> 0 | J15: % 1° SCAGLIONE | K15: =IF(APRI!D36>APRI!C36,APRI!D36,0) -> 0 | L15: =+K15 -> 0 | M15: =+L15 -> 0 | N15: =+M15 -> 0
B16: RESIDUO | D16: =SUM(D14:D15) -> 36.565858 | E16: =SUM(E14:E15) -> 22.122479 | F16: =SUM(F14:F15) -> 5.8211748 | G16: =SUM(G14:G15) -> -10.953839 | J16: tot 1° | K16: =+K14*K15 -> 0 | L16: =+L14*L15 -> 0 | M16: =+M14*M15 -> 0 | N16: =+N14*N15 -> 0
J17: 2° SCAGLIONE | K17: =IF(K13>K14,+K13-K14,0) -> 0 | L17: =IF(L13>L14,+L13-L14,0) -> 0 | M17: =IF(M13>M14,+M13-M14,0) -> 0 | N17: =IF(N13>N14,+N13-N14,0) -> 0
J18: %2° SCAGLIONE | K18: =IF(APRI!D37>APRI!C37,APRI!D37,0) -> 0 | L18: =+K18 -> 0 | M18: =+L18 -> 0 | N18: =+M18 -> 0
B19: credito iva a rimborso | D19: 1 | E19: 2 | F19: 3 | G19: 4 | H19: 5 | J19: tot 2° | K19: =+K17*K18 -> 0 | L19: =+L17*L18 -> 0 | M19: =+M17*M18 -> 0 | N19: =+N17*N18 -> 0
B20: credito iniziale | D20: 0 | E20: =+D28 -> 65 | F20: =+E28 -> 14 | G20: =+F28 -> 0 | H20: =+G28 -> 0 | J20: TOTALE | K20: =+K16+K19 -> 0 | L20: =+L16+L19 -> 0 | M20: =+M16+M19 -> 0 | N20: =+N16+N19 -> 0
B21: chiesto a rimborso nel'anno | D21: =-D15 -> 65 | E21: =-E15 -> 14 | F21: =-F15 -> 0 | G21: =-G15 -> 0 | J21: AFF.AZ. | K21: =IF(K4>(K12+K20),K4,(K12+K20)) -> 0 | L21: =IF(L4>(L12+L20),L4,(L12+L20)) -> 0 | M21: =IF(M4>(M12+M20),M4,(M12+M20)) -> 0 | N21: =IF(N4>(N12+N20),N4,(N12+N20)) -> 0
B22: rimborso riferito all'anno:
B23: 1 | D23: =IF(APRI!$C$107=1,APRI!$C$106,0) -> 0 | E23: =IF(APRI!$C$107=2,APRI!$C$106,0) -> 65 | F23: =IF(APRI!$C$107=3,APRI!$C$106,0) -> 0 | G23: =IF(APRI!$C$107=4,APRI!$C$106,0) -> 0 | H23: =IF(APRI!$C$107=5,APRI!$C$106,0) -> 0 | J23: affitto di azienda
B24: 2 | D24: =IF(APRI!$D$107=1,APRI!$D$106,0) -> 0 | E24: =IF(APRI!$D$107=2,APRI!$D$106,0) -> 0 | F24: =IF(APRI!$D$107=3,APRI!$D$106,0) -> 14 | G24: =IF(APRI!$D$107=4,APRI!$D$106,0) -> 0 | H24: =IF(APRI!$D$107=5,APRI!$D$106,0) -> 0 | J24: scaglioni | K24: su incasso | L24: su vendite
B25: 3 | D25: =IF(APRI!$E$107=1,APRI!$E$106,0) -> 0 | E25: =IF(APRI!$E$107=2,APRI!$E$106,0) -> 0 | F25: =IF(APRI!$E$107=3,APRI!$E$106,0) -> 0 | G25: =IF(APRI!$E$107=4,APRI!$E$106,0) -> 0 | H25: =IF(APRI!$E$107=5,APRI!$E$106,0) -> 0 | J25: =IF(AND(APRI!B36>0.1,APRI!C2>APRI!B36),APRI!B36,IF(APRI!C2<APRI!B36,APRI!C2,0)) -> 0 | K25: =IF(APRI!C36>APRI!D36,J25*APRI!C36,0) -> 0 | L25: =IF(APRI!D36>APRI!C36,J25*APRI!D36,0) -> 0
B26: 4 | D26: =IF(APRI!$F$107=1,APRI!$F$106,0) -> 0 | E26: =IF(APRI!$F$107=2,APRI!$F$106,0) -> 0 | F26: =IF(APRI!$F$107=3,APRI!$F$106,0) -> 0 | G26: =IF(APRI!$F$107=4,APRI!$F$106,0) -> 0 | H26: =IF(APRI!$F$107=5,APRI!$F$106,0) -> 0 | J26: =IF((+APRI!C2-APRI!B36)>0.1,APRI!C2-APRI!B36,0) -> 5800 | K26: =IF(APRI!C37>APRI!D37,J26*APRI!C37,0) -> 0 | L26: =IF(APRI!D37>APRI!C37,J26*APRI!D37,0) -> 0
B27: 5 | J27: =SUM(J25:J26) -> 5800 | K27: =SUM(K25:K26) -> 0 | L27: =SUM(L25:L26) -> 0
B28: credito finale | D28: =+D20+D21-D23-D24-D25-D26-D27 -> 65 | E28: =+E20+E21-E23-E24-E25-E26-E27 -> 14 | F28: =+F20+F21-F23-F24-F25-F26-F27 -> 0 | G28: =+G20+G21-G23-G24-G25-G26-G27 -> 0 | H28: =+H20+H21-H23-H24-H25-H26-H27 -> 0 | J28: TOTALE | K28: =IF(AND(K27>0,K27>APRI!$B$38),K27,IF(AND(K27>0,K27<APRI!$B$38),APRI!$B$38,0)) -> 0 | L28: =IF(AND(L27>0,L27>APRI!$B$38),L27,IF(AND(L27>0,L27<APRI!$B$38),APRI!$B$38,0)) -> 0
B30: CASH FLOW: anno | D30: 1 | E30: 2 | F30: 3 | G30: 4 | I30: TASSE | L30: =+APRI!C51 -> 0.039 | M30: =+APRI!C52 -> 0.24 | N30: TOTALE
B31: RIMBORSO MUTUO | D31: =-E142 -> 0 | E31: =-E147 -> 0 | F31: =-E152 -> 0 | G31: =-K142 -> 0 | I31: ANNO | J31: UTILE-+of | K31: LAVORO | L31: IRAP | M31: IRPEG
B32: INCREMENTO CESPITI | E32: =-APRI!E119 -> 0 | F32: =-APRI!G119 -> 0 | G32: =-APRI!I119 -> 0 | I32: 1 | J32: =+APRI!C138+APRI!C139 -> -155.15583 | K32: =+APRI!C131 -> 510.2 | L32: =IF((+J32+K32)>0,(J32+K32)*$L$30,0) -> 13.846723 | M32: =IF(J32>0,+J32*$M$30,0) -> 0 | N32: =+L32+M32 -> 13.846723
B33: INCASSO P.F.A. anno preced. | E33: =-D34 -> 56.0352 | F33: =-E34 -> 61.8722 | G33: =-F34 -> 67.7092 | I33: 2 | J33: =+APRI!E138+APRI!E139 -> -45.161596 | K33: =+APRI!E131 -> 537.20409 | L33: =IF((+J33+K33)>0,(J33+K33)*$L$30,0) -> 19.189657 | M33: =IF(J33>0,+J33*$M$30,0) -> 0 | N33: =+L33+M33 -> 19.189657
B34: P.F.A. anno corrente | D34: =-F55 -> -56.0352 | E34: =-H55 -> -61.8722 | F34: =-J55 -> -67.7092 | G34: =-L55 -> -69.672767 | I34: 3 | J34: =+APRI!G138+APRI!G139 -> 97.289611 | K34: =+APRI!G131 -> 579.70129 | L34: =IF((+J34+K34)>0,(J34+K34)*$L$30,0) -> 26.402645 | M34: =IF(J34>0,+J34*$M$30,0) -> 23.349507 | N34: =+L34+M34 -> 49.752152
B35: AMMORTAMENTI | D35: =+APRI!C133 -> 27.947143 | E35: =+APRI!E133 -> 27.947143 | F35: =+APRI!G133 -> 27.947143 | G35: =+APRI!I133 -> 27.947143 | I35: 4 | J35: =+APRI!I138+APRI!I139 -> 59.911461 | K35: =+APRI!I131 -> 639.1147 | L35: =IF((+J35+K35)>0,(J35+K35)*$L$30,0) -> 27.26202 | M35: =IF(J35>0,+J35*$M$30,0) -> 14.378751 | N35: =+L35+M35 -> 41.640771
B36: MARGINE OPERATIVO | D36: =APRI!C138 -> -155.49617 | E36: =APRI!E138 -> -40.725621 | F36: =APRI!G138 -> 96.031605 | G36: =APRI!I138 -> 57.029336
B37: ALTRI FONDI (TFR) | D37: =(APRI!C22*APRI!D22+APRI!C23*APRI!D23)*5%+(APRI!C24*APRI!D24)/15 -> 26.21 | E37: =(APRI!E22*APRI!F22+APRI!E23*APRI!F23)*5%+(APRI!E24*APRI!F24)/15 -> 27.783976 | F37: =(APRI!G22*APRI!H22+APRI!G23*APRI!H23)*5%+(APRI!G24*APRI!H24)/15 -> 30.384263 | G37: =(APRI!I22*APRI!J22+APRI!I23*APRI!J23)*5%+(APRI!I24*APRI!J24)/15 -> 31.374643
B38: CREDITO IVA dell'anno | D38: =IF(D14>0,-D14,0) -> -101.56586 | E38: =IF(E14>0,-E14,0) -> -36.122479 | F38: =IF(F14>0,-F14,0) -> -5.8211748 | G38: =IF(G14>0,-G14,0) -> 0 | I38: riporto a nuovo del risultato:
B39: SALDO MOV.FINANZ. | D39: =SUM(D31:D38) -> -258.94009 | E39: =SUM(E31:E38) -> -26.953981 | F39: =SUM(F31:F38) -> 142.70484 | G39: =SUM(G31:G38) -> 114.38755 | I39: anno | J39: risultato
B40: VALORE MEDIO | D40: =D39/2 -> -129.47004 | E40: =E39/2 -> -13.476991 | F40: =F39/2 -> 71.352418 | G40: =G39/2 -> 57.193777 | I40: 1 | J40: =IF(APRI!C141>0,APRI!C141-(APRI!C141*APRI!$C$102),APRI!C141-(APRI!C141*APRI!$C$101)) -> -169.00255
B41: RATEO COSTI (ESPOSIZ.VS.FORN.) | D41: =((-APRI!C128+APRI!C131+APRI!C132+APRI!C136)/12)/(APRI!C9+APRI!C10)*12 -> 63.623067 | E41: =(-APRI!E128+APRI!E131+APRI!E132+APRI!E136)/12 -> 66.912824 | F41: =(-APRI!G128+APRI!G131+APRI!G132+APRI!G136)/12 -> 71.656554 | G41: =(-APRI!I128+APRI!I131+APRI!I132+APRI!I136)/12 -> 77.508818 | I41: 2 | J41: =IF(APRI!E141>0,APRI!E141-(APRI!E141*APRI!$C$102),APRI!E141-(APRI!E141*APRI!$C$101)) -> -64.351253
B42: IVA A DEBITOval.medio | D42: =IF(D14<0,D14/APRI!C9,0) -> 0 | E42: =IF(E14<0,E14/12,0) -> 0 | F42: =IF(F14<0,F14/12,0) -> 0 | G42: =IF(G14<0,G14/12,0) -> -0.91281994 | I42: 3 | J42: =IF(APRI!G141>0,APRI!G141-(APRI!G141*APRI!$C$102),APRI!G141-(APRI!G141*APRI!$C$101)) -> 47.537459
...
